//
//  FutureRecoverTests.swift
//  SimpleFutures
//
//  Created by Troy Stribling on 12/20/14.
//  Copyright (c) 2014 gnos.us. All rights reserved.
//

import UIKit
import XCTest
import SimpleFutures

class FutureRecoverTests : XCTestCase {
    
    override func setUp() {
        super.setUp()
    }
    
    override func tearDown() {
        super.tearDown()
    }
    
    func testSuccessful() {
        let promise = Promise<Bool>()
        let future = promise.future
        let onSuccessExpectation = expectationWithDescription("OnSuccess fulfilled")
        let onSuccessRecoveryExpectation = expectationWithDescription("OnSuccess fulfilled for recovered future")
        future.onSuccess {value in
            XCTAssert(value, "future onSuccess value invalid")
            onSuccessExpectation.fulfill()
        }
        future.onFailure {error in
            XCTAssert(false, "future onFailure called")
        }
        let recovered = future.recover {error -> Try<Bool> in
            XCTAssert(false, "recover called")
            return Try(false)
        }
        recovered.onSuccess {value in
            XCTAssert(value, "recovered onSuccess value invalid")
            onSuccessRecoveryExpectation.fulfill()
        }
        recovered.onFailure {error in
            XCTAssert(false, "recovered onFailure called")
        }
        promise.success(true)
        waitForExpectationsWithTimeout(2) {error in
            XCTAssertNil(error, "\(error)")
        }
    }
    
    func testSuccessfulRecovery() {
        let promise = Promise<Bool>()
        let future = promise.future
        let onFailureExpectation = expectationWithDescription("OnFailure fulfilled")
        let onSuccessRecoveryExpectation = expectationWithDescription("OnSuccess fulfilled for recovered future")
        let recoverExpectation = expectationWithDescription("recover fulfilled")
        future.onSuccess {value in
            XCTAssert(false, "future onSuccess called")
        }
        future.onFailure {error in
            onFailureExpectation.fulfill()
        }
        let recovered = future.recover {error -> Try<Bool> in
            recoverExpectation.fulfill()
            return Try(false)
        }
        recovered.onSuccess {value in
            XCTAssertFalse(value, "recovered onSuccess invalid value")
            onSuccessRecoveryExpectation.fulfill()
        }
        recovered.onFailure {error in
            XCTAssert(false, "recovered onFailure called")
        }
        promise.failure(TestFailure.error)
        waitForExpectationsWithTimeout(2) {error in
            XCTAssertNil(error, "\(error)")
        }
    }
    
    func testFailedRecovery() {
        let promise = Promise<Bool>()
        let future = promise.future
        let onFailureExpectation = expectationWithDescription("OnFailure fulfilled")
        let onFailureRecoveryExpectation = expectationWithDescription("OnFailure fulfilled for recovered future")
        let recoverExpectation = expectationWithDescription("recover fulfilled")
        future.onSuccess {value in
            XCTAssert(false, "future onSuccess called")
        }
        future.onFailure {error in
            onFailureExpectation.fulfill()
        }
        let recovered = future.recover {error -> Try<Bool> in
            recoverExpectation.fulfill()
            return Try<Bool>(TestFailure.error)
        }
        recovered.onSuccess {value in
            XCTAssert(false, "recovered onSuccess callsd")
        }
        recovered.onFailure {error in
            onFailureRecoveryExpectation.fulfill()
        }
        promise.failure(TestFailure.error)
        waitForExpectationsWithTimeout(2) {error in
            XCTAssertNil(error, "\(error)")
        }
    }
    
}
